Workbook

Sheet Medicine Master Table
A1: ISLAMIYA PHARMACY
A2: Medicine ID | B2: Medicine Name | C2: Generic Name | D2: Dosage Form | E2: Indication | F2: Cost Price | G2: Pcs per Box | H2: Cost Per Pc | I2: Unit Price | J2: Total Received | K2: Total Sold | L2: Current Stock | M2: Min Stock | N2: Expiry Date | O2: Stock Status | P2: Total Profit | Q2: Lead Time | R2: Annual Consumption Value | S2: Cumulative % | T2: ABC Class
A3: AL-001 | B3: Fenadin 120mg | C3: Fexofenadine | D3: Tablet | E3: Allergy / Antihistamine | F3: 396.23 | G3: 50 | H3: =Table1[[#This Row],[Cost Price]]/Table1[[#This Row],[Pcs per Box]] -> 7.9246 | I3: 9 | J3: =SUMIF('Stock In'!C:C, Table1[[#This Row],[Medicine ID]], 'Stock In'!E:E) * Table1[[#This Row],[Pcs per Box]] -> 400 | K3: =SUMIF('Sales Log Table'!C:C, Table1[[#This Row],[Medicine ID]], 'Sales Log Table'!E:E) -> 0 | L3: =Table1[[#This Row],[Total Received]] - Table1[[#This Row],[Total Sold]] -> 400 | M3: 50 | N3: 46563 | O3: =IF(Table1[[#This Row],[Current Stock]] <= Table1[[#This Row],[Min Stock]], "REORDER NOW", "Good") -> Good | P3: =(Table1[[#This Row],[Unit Price]] - Table1[[#This Row],[Cost Per Pc]]) * Table1[[#This Row],[Total Sold]] -> 0 | R3: =(Table1[[#This Row],[Total Received]] / Table1[[#This Row],[Pcs per Box]]) * Table1[[#This Row],[Cost Price]] -> 3169.84 | S3: =SUM($R$3:Table1[[#This Row],[Annual Consumption Value]]) / SUM(Table1[Annual Consumption Value]) -> 0.011639752 | T3: =IF(Table1[[#This Row],[Cumulative %]]<=0.8, "A", IF(Table1[[#This Row],[Cumulative %]]<=0.95, "B", "C")) -> A
A4: AL-002 | B4: Fenadin 180mg | C4: Fexofenadine | D4: Tablet | E4: Allergy / Antihistamine | F4: =(Table1[[#This Row],[Unit Price]] * 0.9) * Table1[[#This Row],[Pcs per Box]] -> 180 | G4: 20 | H4: =Table1[[#This Row],[Cost Price]]/Table1[[#This Row],[Pcs per Box]] -> 9 | I4: 10 | J4: =SUMIF('Stock In'!C:C, Table1[[#This Row],[Medicine ID]], 'Stock In'!E:E) * Table1[[#This Row],[Pcs per Box]] -> 100 | K4: =SUMIF('Sales Log Table'!C:C, Table1[[#This Row],[Medicine ID]], 'Sales Log Table'!E:E) -> 0 | L4: =Table1[[#This Row],[Total Received]] - Table1[[#This Row],[Total Sold]] -> 100 | M4: 60 | N4: 46563 | O4: =IF(Table1[[#This Row],[Current Stock]] <= Table1[[#This Row],[Min Stock]], "REORDER NOW", "Good") -> Good | P4: =(Table1[[#This Row],[Unit Price]] - Table1[[#This Row],[Cost Per Pc]]) * Table1[[#This Row],[Total Sold]] -> 0 | R4: =(Table1[[#This Row],[Total Received]] / Table1[[#This Row],[Pcs per Box]]) * Table1[[#This Row],[Cost Price]] -> 900 | S4: =SUM($R$3:Table1[[#This Row],[Annual Consumption Value]]) / SUM(Table1[Annual Consumption Value]) -> 0.01494458 | T4: =IF(Table1[[#This Row],[Cumulative %]]<=0.8, "A", IF(Table1[[#This Row],[Cumulative %]]<=0.95, "B", "C")) -> A
A5: AL-003 | B5: Fexo 120mg | C5: Fexofenadine | D5: Tablet | E5: Allergy / Antihistamine | F5: =(Table1[[#This Row],[Unit Price]] * 0.9) * Table1[[#This Row],[Pcs per Box]] -> 405 | G5: 50 | H5: =Table1[[#This Row],[Cost Price]]/Table1[[#This Row],[Pcs per Box]] -> 8.1 | I5: 9 | J5: =SUMIF('Stock In'!C:C, Table1[[#This Row],[Medicine ID]], 'Stock In'!E:E) * Table1[[#This Row],[Pcs per Box]] -> 150 | K5: =SUMIF('Sales Log Table'!C:C, Table1[[#This Row],[Medicine ID]], 'Sales Log Table'!E:E) -> 0 | L5: =Table1[[#This Row],[Total Received]] - Table1[[#This Row],[Total Sold]] -> 150 | M5: 50 | N5: 46563 | O5: =IF(Table1[[#This Row],[Current Stock]] <= Table1[[#This Row],[Min Stock]], "REORDER NOW", "Good") -> Good | P5: =(Table1[[#This Row],[Unit Price]] - Table1[[#This Row],[Cost Per Pc]]) * Table1[[#This Row],[Total Sold]] -> 0 | R5: =(Table1[[#This Row],[Total Received]] / Table1[[#This Row],[Pcs per Box]]) * Table1[[#This Row],[Cost Price]] -> 1215 | S5: =SUM($R$3:Table1[[#This Row],[Annual Consumption Value]]) / SUM(Table1[Annual Consumption Value]) -> 0.019406098 | T5: =IF(Table1[[#This Row],[Cumulative %]]<=0.8, "A", IF(Table1[[#This Row],[Cumulative %]]<=0.95, "B", "C")) -> A
A6: AL-004 | B6: Fexo 180mg | C6: Fexofenadine | D6: Tablet | E6: Allergy / Antihistamine | F6: =(Table1[[#This Row],[Unit Price]] * 0.9) * Table1[[#This Row],[Pcs per Box]] -> 324 | G6: 30 | H6: =Table1[[#This Row],[Cost Price]]/Table1[[#This Row],[Pcs per Box]] -> 10.8 | I6: 12 | J6: =SUMIF('Stock In'!C:C, Table1[[#This Row],[Medicine ID]], 'Stock In'!E:E) * Table1[[#This Row],[Pcs per Box]] -> 60 | K6: =SUMIF('Sales Log Table'!C:C, Table1[[#This Row],[Medicine ID]], 'Sales Log Table'!E:E) -> 0 | L6: =Table1[[#This Row],[Total Received]] - Table1[[#This Row],[Total Sold]] -> 60 | M6: 30 | N6: 46563 | O6: =IF(Table1[[#This Row],[Current Stock]] <= Table1[[#This Row],[Min Stock]], "REORDER NOW", "Good") -> Good | P6: =(Table1[[#This Row],[Unit Price]] - Table1[[#This Row],[Cost Per Pc]]) * Table1[[#This Row],[Total Sold]] -> 0 | R6: =(Table1[[#This Row],[Total Received]] / Table1[[#This Row],[Pcs per Box]]) * Table1[[#This Row],[Cost Price]] -> 648 | S6: =SUM($R$3:Table1[[#This Row],[Annual Consumption Value]]) / SUM(Table1[Annual Consumption Value]) -> 0.021785574 | T6: =IF(Table1[[#This Row],[Cumulative %]]<=0.8, "A", IF(Table1[[#This Row],[Cumulative %]]<=0.95, "B", "C")) -> A
A7: AL-005 | B7: Alatrol | C7: Cetrizine | D7: Tablet | E7: Allergy / Antihistamine | F7: =(Table1[[#This Row],[Unit Price]] * 0.9) * Table1[[#This Row],[Pcs per Box]] -> 405 | G7: 150 | H7: =Table1[[#This Row],[Cost Price]]/Table1[[#This Row],[Pcs per Box]] -> 2.7 | I7: 3 | J7: =SUMIF('Stock In'!C:C, Table1[[#This Row],[Medicine ID]], 'Stock In'!E:E) * Table1[[#This Row],[Pcs per Box]] -> 300 | K7: =SUMIF('Sales Log Table'!C:C, Table1[[#This Row],[Medicine ID]], 'Sales Log Table'!E:E) -> 10 | L7: =Table1[[#This Row],[Total Received]] - Table1[[#This Row],[Total Sold]] -> 290 | M7: 40 | N7: 46563 | O7: =IF(Table1[[#This Row],[Current Stock]] <= Table1[[#This Row],[Min Stock]], "REORDER NOW", "Good") -> Good | P7: =(Table1[[#This Row],[Unit Price]] - Table1[[#This Row],[Cost Per Pc]]) * Table1[[#This Row],[Total Sold]] -> 3 | R7: =(Table1[[#This Row],[Total Received]] / Table1[[#This Row],[Pcs per Box]]) * Table1[[#This Row],[Cost Price]] -> 810 | S7: =SUM($R$3:Table1[[#This Row],[Annual Consumption Value]]) / SUM(Table1[Annual Consumption Value]) -> 0.02475992 | T7: =IF(Table1[[#This Row],[Cumulative %]]<=0.8, "A", IF(Table1[[#This Row],[Cumulative %]]<=0.95, "B", "C")) -> A
A8: AL-006 | B8: Alat | C8: Cetrizine | D8: Tablet | E8: Allergy / Antihistamine | F8: =(Table1[[#This Row],[Unit Price]] * 0.9) * Table1[[#This Row],[Pcs per Box]] -> 225 | G8: 100 | H8: =Table1[[#This Row],[Cost Price]]/Table1[[#This Row],[Pcs per Box]] -> 2.25 | I8: 2.5 | J8: =SUMIF('Stock In'!C:C, Table1[[#This Row],[Medicine ID]], 'Stock In'!E:E) * Table1[[#This Row],[Pcs per Box]] -> 200 | K8: =SUMIF('Sales Log Table'!C:C, Table1[[#This Row],[Medicine ID]], 'Sales Log Table'!E:E) -> 0 | L8: =Table1[[#This Row],[Total Received]] - Table1[[#This Row],[Total Sold]] -> 200 | M8: 87 | N8: 46563 | O8: =IF(Table1[[#This Row],[Current Stock]] <= Table1[[#This Row],[Min Stock]], "REORDER NOW", "Good") -> Good | P8: =(Table1[[#This Row],[Unit Price]] - Table1[[#This Row],[Cost Per Pc]]) * Table1[[#This Row],[Total Sold]] -> 0 | R8: =(Table1[[#This Row],[Total Received]] / Table1[[#This Row],[Pcs per Box]]) * Table1[[#This Row],[Cost Price]] -> 450 | S8: =SUM($R$3:Table1[[#This Row],[Annual Consumption Value]]) / SUM(Table1[Annual Consumption Value]) -> 0.026412334 | T8: =IF(Table1[[#This Row],[Cumulative %]]<=0.8, "A", IF(Table1[[#This Row],[Cumulative %]]<=0.95, "B", "C")) -> A
A9: AL-007 | B9: Atrizin | C9: Cetrizine | D9: Tablet | E9: Allergy / Antihistamine | F9: =(Table1[[#This Row],[Unit Price]] * 0.9) * Table1[[#This Row],[Pcs per Box]] -> 405 | G9: 150 | H9: =Table1[[#This Row],[Cost Price]]/Table1[[#This Row],[Pcs per Box]] -> 2.7 | I9: 3 | J9: =SUMIF('Stock In'!C:C, Table1[[#This Row],[Medicine ID]], 'Stock In'!E:E) * Table1[[#This Row],[Pcs per Box]] -> 600 | K9: =SUMIF('Sales Log Table'!C:C, Table1[[#This Row],[Medicine ID]], 'Sales Log Table'!E:E) -> 0 | L9: =Table1[[#This Row],[Total Received]] - Table1[[#This Row],[Total Sold]] -> 600 | M9: 67 | N9: 46563 | O9: =IF(Table1[[#This Row],[Current Stock]] <= Table1[[#This Row],[Min Stock]], "REORDER NOW", "Good") -> Good | P9: =(Table1[[#This Row],[Unit Price]] - Table1[[#This Row],[Cost Per Pc]]) * Table1[[#This Row],[Total Sold]] -> 0 | R9: =(Table1[[#This Row],[Total Received]] / Table1[[#This Row],[Pcs per Box]]) * Table1[[#This Row],[Cost Price]] -> 1620 | S9: =SUM($R$3:Table1[[#This Row],[Annual Consumption Value]]) / SUM(Table1[Annual Consumption Value]) -> 0.032361025 | T9: =IF(Table1[[#This Row],[Cumulative %]]<=0.8, "A", IF(Table1[[#This Row],[Cumulative %]]<=0.95, "B", "C")) -> A
A10: AL-008 | B10: Atrizin 15ml | C10: Cetrizine | D10: PD | E10: Allergy / Antihistamine | F10: =(Table1[[#This Row],[Unit Price]] * 0.9) * Table1[[#This Row],[Pcs per Box]] -> 22.5 | G10: 1 | H10: =Table1[[#This Row],[Cost Price]]/Table1[[#This Row],[Pcs per Box]] -> 22.5 | I10: 25 | J10: =SUMIF('Stock In'!C:C, Table1[[#This Row],[Medicine ID]], 'Stock In'!E:E) * Table1[[#This Row],[Pcs per Box]] -> 10 | K10: =SUMIF('Sales Log Table'!C:C, Table1[[#This Row],[Medicine ID]], 'Sales Log Table'!E:E) -> 0 | L10: =Table1[[#This Row],[Total Received]] - Table1[[#This Row],[Total Sold]] -> 10 | M10: 3 | N10: 46563 | O10: =IF(Table1[[#This Row],[Current Stock]] <= Table1[[#This Row],[Min Stock]], "REORDER NOW", "Good") -> Good | P10: =(Table1[[#This Row],[Unit Price]] - Table1[[#This Row],[Cost Per Pc]]) * Table1[[#This Row],[Total Sold]] -> 0 | R10: =(Table1[[#This Row],[Total Received]] / Table1[[#This Row],[Pcs per Box]]) * Table1[[#This Row],[Cost Price]] -> 225 | S10: =SUM($R$3:Table1[[#This Row],[Annual Consumption Value]]) / SUM(Table1[Annual Consumption Value]) -> 0.033187232 | T10: =IF(Table1[[#This Row],[Cumulative %]]<=0.8, "A", IF(Table1[[#This Row],[Cumulative %]]<=0.95, "B", "C")) -> A
A11: AL-009 | B11: Alatrol | C11: Cetrizine | D11: PD | E11: Allergy / Antihistamine | F11: =(Table1[[#This Row],[Unit Price]] * 0.9) * Table1[[#This Row],[Pcs per Box]] -> 25.2 | G11: 1 | H11: =Table1[[#This Row],[Cost Price]]/Table1[[#This Row],[Pcs per Box]] -> 25.2 | I11: 28 | J11: =SUMIF('Stock In'!C:C, Table1[[#This Row],[Medicine ID]], 'Stock In'!E:E) * Table1[[#This Row],[Pcs per Box]] -> 10 | K11: =SUMIF('Sales Log Table'!C:C, Table1[[#This Row],[Medicine ID]], 'Sales Log Table'!E:E) -> 0 | L11: =Table1[[#This Row],[Total Received]] - Table1[[#This Row],[Total Sold]] -> 10 | M11: 5 | N11: 46563 | O11: =IF(Table1[[#This Row],[Current Stock]] <= Table1[[#This Row],[Min Stock]], "REORDER NOW", "Good") -> Good | P11: =(Table1[[#This Row],[Unit Price]] - Table1[[#This Row],[Cost Per Pc]]) * Table1[[#This Row],[Total Sold]] -> 0 | R11: =(Table1[[#This Row],[Total Received]] / Table1[[#This Row],[Pcs per Box]]) * Table1[[#This Row],[Cost Price]] -> 252 | S11: =SUM($R$3:Table1[[#This Row],[Annual Consumption Value]]) / SUM(Table1[Annual Consumption Value]) -> 0.034112584 | T11: =IF(Table1[[#This Row],[Cumulative %]]<=0.8, "A", IF(Table1[[#This Row],[Cumulative %]]<=0.95, "B", "C")) -> A
A12: AL-010 | B12: Alatrol 60ml | C12: Cetrizine | D12: Syrup | E12: Allergy / Antihistamine | F12: =(Table1[[#This Row],[Unit Price]] * 0.9) * Table1[[#This Row],[Pcs per Box]] -> 31.5 | G12: 1 | H12: =Table1[[#This Row],[Cost Price]]/Table1[[#This Row],[Pcs per Box]] -> 31.5 | I12: 35 | J12: =SUMIF('Stock In'!C:C, Table1[[#This Row],[Medicine ID]], 'Stock In'!E:E) * Table1[[#This Row],[Pcs per Box]] -> 5 | K12: =SUMIF('Sales Log Table'!C:C, Table1[[#This Row],[Medicine ID]], 'Sales Log Table'!E:E) -> 0 | L12: =Table1[[#This Row],[Total Received]] - Table1[[#This Row],[Total Sold]] -> 5 | M12: 2 | N12: 46563 | O12: =IF(Table1[[#This Row],[Current Stock]] <= Table1[[#This Row],[Min Stock]], "REORDER NOW", "Good") -> Good | P12: =(Table1[[#This Row],[Unit Price]] - Table1[[#This Row],[Cost Per Pc]]) * Table1[[#This Row],[Total Sold]] -> 0 | R12: =(Table1[[#This Row],[Total Received]] / Table1[[#This Row],[Pcs per Box]]) * Table1[[#This Row],[Cost Price]] -> 157.5 | S12: =SUM($R$3:Table1[[#This Row],[Annual Consumption Value]]) / SUM(Table1[Annual Consumption Value]) -> 0.034690929 | T12: =IF(Table1[[#This Row],[Cumulative %]]<=0.8, "A", IF(Table1[[#This Row],[Cumulative %]]<=0.95, "B", "C")) -> A
A13: AL-011 | B13: Bilastin 20mg | C13: Bilastine | D13: Tablet | E13: Allergy / Antihistamine | F13: 422.43 | G13: 30 | H13: =Table1[[#This Row],[Cost Price]]/Table1[[#This Row],[Pcs per Box]] -> 14.081 | I13: 16 | J13: =SUMIF('Stock In'!C:C, Table1[[#This Row],[Medicine ID]], 'Stock In'!E:E) * Table1[[#This Row],[Pcs per Box]] -> 180 | K13: =SUMIF('Sales Log Table'!C:C, Table1[[#This Row],[Medicine ID]], 'Sales Log Table'!E:E) -> 0 | L13: =Table1[[#This Row],[Total Received]] - Table1[[#This Row],[Total Sold]] -> 180 | M13: 30 | N13: 46563 | O13: =IF(Table1[[#This Row],[Current Stock]] <= Table1[[#This Row],[Min Stock]], "REORDER NOW", "Good") -> Good | P13: =(Table1[[#This Row],[Unit Price]] - Table1[[#This Row],[Cost Per Pc]]) * Table1[[#This Row],[Total Sold]] -> 0 | R13: =(Table1[[#This Row],[Total Received]] / Table1[[#This Row],[Pcs per Box]]) * Table1[[#This Row],[Cost Price]] -> 2534.58 | S13: =SUM($R$3:Table1[[#This Row],[Annual Consumption Value]]) / SUM(Table1[Annual Consumption Value]) -> 0.043997986 | T13: =IF(Table1[[#This Row],[Cumulative %]]<=0.8, "A", IF(Table1[[#This Row],[Cumulative %]]<=0.95, "B", "C")) -> A
A14: AL-012 | B14: M-Lucas 10 | C14: Montelukast | D14: Tablet | E14: Asthma / Allergic Rhinitis | F14: 448.83 | G14: 30 | H14: =Table1[[#This Row],[Cost Price]]/Table1[[#This Row],[Pcs per Box]] -> 14.961 | I14: 17 | J14: =SUMIF('Stock In'!C:C, Table1[[#This Row],[Medicine ID]], 'Stock In'!E:E) * Table1[[#This Row],[Pcs per Box]] -> 450 | K14: =SUMIF('Sales Log Table'!C:C, Table1[[#This Row],[Medicine ID]], 'Sales Log Table'!E:E) -> 0 | L14: =Table1[[#This Row],[Total Received]] - Table1[[#This Row],[Total Sold]] -> 450 | M14: 30 | N14: 46563 | O14: =IF(Table1[[#This Row],[Current Stock]] <= Table1[[#This Row],[Min Stock]], "REORDER NOW", "Good") -> Good | P14: =(Table1[[#This Row],[Unit Price]] - Table1[[#This Row],[Cost Per Pc]]) * Table1[[#This Row],[Total Sold]] -> 0 | R14: =(Table1[[#This Row],[Total Received]] / Table1[[#This Row],[Pcs per Box]]) * Table1[[#This Row],[Cost Price]] -> 6732.45 | S14: =SUM($R$3:Table1[[#This Row],[Annual Consumption Value]]) / SUM(Table1[Annual Consumption Value]) -> 0.068719753 | T14: =IF(Table1[[#This Row],[Cumulative %]]<=0.8, "A", IF(Table1[[#This Row],[Cumulative %]]<=0.95, "B", "C")) -> A
A15: AL-013 | B15: Lumona 10 | C15: Montelukast | D15: Tablet | E15: Asthma / Allergic Rhinitis | F15: 443.56 | G15: 42 | H15: =Table1[[#This Row],[Cost Price]]/Table1[[#This Row],[Pcs per Box]] -> 10.560952 | I15: 12 | J15: =SUMIF('Stock In'!C:C, Table1[[#This Row],[Medicine ID]], 'Stock In'!E:E) * Table1[[#This Row],[Pcs per Box]] -> 84 | K15: =SUMIF('Sales Log Table'!C:C, Table1[[#This Row],[Medicine ID]], 'Sales Log Table'!E:E) -> 0 | L15: =Table1[[#This Row],[Total Received]] - Table1[[#This Row],[Total Sold]] -> 84 | M15: 42 | N15: 46563 | O15: =IF(Table1[[#This Row],[Current Stock]] <= Table1[[#This Row],[Min Stock]], "REORDER NOW", "Good") -> Good | P15: =(Table1[[#This Row],[Unit Price]] - Table1[[#This Row],[Cost Per Pc]]) * Table1[[#This Row],[Total Sold]] -> 0 | R15: =(Table1[[#This Row],[Total Received]] / Table1[[#This Row],[Pcs per Box]]) * Table1[[#This Row],[Cost Price]] -> 887.12 | S15: =SUM($R$3:Table1[[#This Row],[Annual Consumption Value]]) / SUM(Table1[Annual Consumption Value]) -> 0.071977286 | T15: =IF(Table1[[#This Row],[Cumulative %]]<=0.8, "A", IF(Table1[[#This Row],[Cumulative %]]<=0.95, "B", "C")) -> A
A16: AL-014 | B16: Superitra 65mg | C16: Itraconazole | D16: Capsule | E16: Antifungal | F16: 528.04 | G16: 30 | H16: =Table1[[#This Row],[Cost Price]]/Table1[[#This Row],[Pcs per Box]] -> 17.601333 | I16: 20 | J16: =SUMIF('Stock In'!C:C, Table1[[#This Row],[Medicine ID]], 'Stock In'!E:E) * Table1[[#This Row],[Pcs per Box]] -> 150 | K16: =SUMIF('Sales Log Table'!C:C, Table1[[#This Row],[Medicine ID]], 'Sales Log Table'!E:E) -> 0 | L16: =Table1[[#This Row],[Total Received]] - Table1[[#This Row],[Total Sold]] -> 150 | M16: 30 | N16: 46563 | O16: =IF(Table1[[#This Row],[Current Stock]] <= Table1[[#This Row],[Min Stock]], "REORDER NOW", "Good") -> Good | P16: =(Table1[[#This Row],[Unit Price]] - Table1[[#This Row],[Cost Per Pc]]) * Table1[[#This Row],[Total Sold]] -> 0 | R16: =(Table1[[#This Row],[Total Received]] / Table1[[#This Row],[Pcs per Box]]) * Table1[[#This Row],[Cost Price]] -> 2640.2 | S16: =SUM($R$3:Table1[[#This Row],[Annual Consumption Value]]) / SUM(Table1[Annual Consumption Value]) -> 0.081672183 | T16: =IF(Table1[[#This Row],[Cumulative %]]<=0.8, "A", IF(Table1[[#This Row],[Cumulative %]]<=0.95, "B", "C")) -> A
A17: AL-015 | B17: Ebatin | C17: Ebastine | D17: Tablet | E17: Allergy / Antihistamine | F17: 528.04 | G17: 60 | H17: =Table1[[#This Row],[Cost Price]]/Table1[[#This Row],[Pcs per Box]] -> 8.8006667 | I17: 10 | J17: =SUMIF('Stock In'!C:C, Table1[[#This Row],[Medicine ID]], 'Stock In'!E:E) * Table1[[#This Row],[Pcs per Box]] -> 300 | K17: =SUMIF('Sales Log Table'!C:C, Table1[[#This Row],[Medicine ID]], 'Sales Log Table'!E:E) -> 10 | L17: =Table1[[#This Row],[Total Received]] - Table1[[#This Row],[Total Sold]] -> 290 | M17: 60 | N17: 46563 | O17: =IF(Table1[[#This Row],[Current Stock]] <= Table1[[#This Row],[Min Stock]], "REORDER NOW", "Good") -> Good | P17: =(Table1[[#This Row],[Unit Price]] - Table1[[#This Row],[Cost Per Pc]]) * Table1[[#This Row],[Total Sold]] -> 11.993333 | R17: =(Table1[[#This Row],[Total Received]] / Table1[[#This Row],[Pcs per Box]]) * Table1[[#This Row],[Cost Price]] -> 2640.2 | S17: =SUM($R$3:Table1[[#This Row],[Annual Consumption Value]]) / SUM(Table1[Annual Consumption Value]) -> 0.09136708 | T17: =IF(Table1[[#This Row],[Cumulative %]]<=0.8, "A", IF(Table1[[#This Row],[Cumulative %]]<=0.95, "B", "C")) -> A
A18: AL-016 | B18: Bilbest 20mg | C18: Bilastine | D18: Tablet | E18: Allergy / Antihistamine | F18: 396.03 | G18: 30 | H18: =Table1[[#This Row],[Cost Price]]/Table1[[#This Row],[Pcs per Box]] -> 13.201 | I18: 15 | J18: =SUMIF('Stock In'!C:C, Table1[[#This Row],[Medicine ID]], 'Stock In'!E:E) * Table1[[#This Row],[Pcs per Box]] -> 600 | K18: =SUMIF('Sales Log Table'!C:C, Table1[[#This Row],[Medicine ID]], 'Sales Log Table'!E:E) -> 10 | L18: =Table1[[#This Row],[Total Received]] - Table1[[#This Row],[Total Sold]] -> 590 | M18: 50 | O18: =IF(Table1[[#This Row],[Current Stock]] <= Table1[[#This Row],[Min Stock]], "REORDER NOW", "Good") -> Good | P18: =(Table1[[#This Row],[Unit Price]] - Table1[[#This Row],[Cost Per Pc]]) * Table1[[#This Row],[Total Sold]] -> 17.99 | R18: =(Table1[[#This Row],[Total Received]] / Table1[[#This Row],[Pcs per Box]]) * Table1[[#This Row],[Cost Price]] -> 7920.6 | S18: =SUM($R$3:Table1[[#This Row],[Annual Consumption Value]]) / SUM(Table1[Annual Consumption Value]) -> 0.12045177 | T18: =IF(Table1[[#This Row],[Cumulative %]]<=0.8, "A", IF(Table1[[#This Row],[Cumulative %]]<=0.95, "B", "C")) -> A
A19: AL-017 | B19: Dexpoten Plus 100ml | C19: Dextromethorphan + Phenylephrine + Triprolidine | D19: Syrup | E19: Cough / Sneezing | F19: 96.83 | G19: 1 | H19: =Table1[[#This Row],[Cost Price]]/Table1[[#This Row],[Pcs per Box]] -> 96.83 | I19: 110 | J19: =SUMIF('Stock In'!C:C, Table1[[#This Row],[Medicine ID]], 'Stock In'!E:E) * Table1[[#This Row],[Pcs per Box]] -> 24 | K19: =SUMIF('Sales Log Table'!C:C, Table1[[#This Row],[Medicine ID]], 'Sales Log Table'!E:E) -> 0 | L19: =Table1[[#This Row],[Total Received]] - Table1[[#This Row],[Total Sold]] -> 24 | M19: 1 | N19: 46563 | O19: =IF(Table1[[#This Row],[Current Stock]] <= Table1[[#This Row],[Min Stock]], "REORDER NOW", "Good") -> Good | P19: =(Table1[[#This Row],[Unit Price]] - Table1[[#This Row],[Cost Per Pc]]) * Table1[[#This Row],[Total Sold]] -> 0 | R19: =(Table1[[#This Row],[Total Received]] / Table1[[#This Row],[Pcs per Box]]) * Table1[[#This Row],[Cost Price]] -> 2323.92 | S19: =SUM($R$3:Table1[[#This Row],[Annual Consumption Value]]) / SUM(Table1[Annual Consumption Value]) -> 0.12898528 | T19: =IF(Table1[[#This Row],[Cumulative %]]<=0.8, "A", IF(Table1[[#This Row],[Cumulative %]]<=0.95, "B", "C")) -> A
A20: AL-018 | B20: Itrakill SB 65mg | C20: Itraconazole | D20: Capsule | E20: Antifungal | F20: 528 | G20: 30 | H20: =Table1[[#This Row],[Cost Price]]/Table1[[#This Row],[Pcs per Box]] -> 17.6 | I20: 20 | J20: =SUMIF('Stock In'!C:C, Table1[[#This Row],[Medicine ID]], 'Stock In'!E:E) * Table1[[#This Row],[Pcs per Box]] -> 150 | K20: =SUMIF('Sales Log Table'!C:C, Table1[[#This Row],[Medicine ID]], 'Sales Log Table'!E:E) -> 0 | L20: =Table1[[#This Row],[Total Received]] - Table1[[#This Row],[Total Sold]] -> 150 | M20: 30 | N20: 46563 | O20: =IF(Table1[[#This Row],[Current Stock]] <= Table1[[#This Row],[Min Stock]], "REORDER NOW", "Good") -> Good | P20: =(Table1[[#This Row],[Unit Price]] - Table1[[#This Row],[Cost Per Pc]]) * Table1[[#This Row],[Total Sold]] -> 0 | R20: =(Table1[[#This Row],[Total Received]] / Table1[[#This Row],[Pcs per Box]]) * Table1[[#This Row],[Cost Price]] -> 2640 | S20: =SUM($R$3:Table1[[#This Row],[Annual Consumption Value]]) / SUM(Table1[Annual Consumption Value]) -> 0.13867944 | T20: =IF(Table1[[#This Row],[Cumulative %]]<=0.8, "A", IF(Table1[[#This Row],[Cumulative %]]<=0.95, "B", "C")) -> A
A21: AL-019 | B21: Mebolin 50mg | C21: Mebhydrolin Napadisylate | D21: Tablet | E21: Allergy | F21: 264 | G21: 100 | H21: =Table1[[#This Row],[Cost Price]]/Table1[[#This Row],[Pcs per Box]] -> 2.64 | I21: 3 | J21: =SUMIF('Stock In'!C:C, Table1[[#This Row],[Medicine ID]], 'Stock In'!E:E) * Table1[[#This Row],[Pcs per Box]] -> 500 | K21: =SUMIF('Sales Log Table'!C:C, Table1[[#This Row],[Medicine ID]], 'Sales Log Table'!E:E) -> 0 | L21: =Table1[[#This Row],[Total Received]] - Table1[[#This Row],[Total Sold]] -> 500 | M21: 100 | N21: 46563 | O21: =IF(Table1[[#This Row],[Current Stock]] <= Table1[[#This Row],[Min Stock]], "REORDER NOW", "Good") -> Good | P21: =(Table1[[#This Row],[Unit Price]] - Table1[[#This Row],[Cost Per Pc]]) * Table1[[#This Row],[Total Sold]] -> 0 | R21: =(Table1[[#This Row],[Total Received]] / Table1[[#This Row],[Pcs per Box]]) * Table1[[#This Row],[Cost Price]] -> 1320 | S21: =SUM($R$3:Table1[[#This Row],[Annual Consumption Value]]) / SUM(Table1[Annual Consumption Value]) -> 0.14352652 | T21: =IF(Table1[[#This Row],[Cumulative %]]<=0.8, "A", IF(Table1[[#This Row],[Cumulative %]]<=0.95, "B", "C")) -> A
A22: AL-020 | B22: Telfadin 180mg | C22: Fexofenadine | D22: Tablet | E22: Allergy / Antihistamine | F22: 176.02 | G22: 20 | H22: =Table1[[#This Row],[Cost Price]]/Table1[[#This Row],[Pcs per Box]] -> 8.801 | I22: 10 | J22: =SUMIF('Stock In'!C:C, Table1[[#This Row],[Medicine ID]], 'Stock In'!E:E) * Table1[[#This Row],[Pcs per Box]] -> 200 | K22: =SUMIF('Sales Log Table'!C:C, Table1[[#This Row],[Medicine ID]], 'Sales Log Table'!E:E) -> 0 | L22: =Table1[[#This Row],[Total Received]] - Table1[[#This Row],[Total Sold]] -> 200 | O22: =IF(Table1[[#This Row],[Current Stock]] <= Table1[[#This Row],[Min Stock]], "REORDER NOW", "Good") -> Good | P22: =(Table1[[#This Row],[Unit Price]] - Table1[[#This Row],[Cost Per Pc]]) * Table1[[#This Row],[Total Sold]] -> 0 | R22: =(Table1[[#This Row],[Total Received]] / Table1[[#This Row],[Pcs per Box]]) * Table1[[#This Row],[Cost Price]] -> 1760.2 | S22: =SUM($R$3:Table1[[#This Row],[Annual Consumption Value]]) / SUM(Table1[Annual Consumption Value]) -> 0.14999003 | T22: =IF(Table1[[#This Row],[Cumulative %]]<=0.8, "A", IF(Table1[[#This Row],[Cumulative %]]<=0.95, "B", "C")) -> A
A23: AN-001 | B23: Flubac 250 | C23: Flucloxacillin Sodium | D23: Capsule | E23: Antibiotic | F23: =(Table1[[#This Row],[Unit Price]] * 0.9) * Table1[[#This Row],[Pcs per Box]] -> 374.4 | G23: 52 | H23: =Table1[[#This Row],[Cost Price]]/Table1[[#This Row],[Pcs per Box]] -> 7.2 | I23: 8 | J23: =SUMIF('Stock In'!C:C, Table1[[#This Row],[Medicine ID]], 'Stock In'!E:E) * Table1[[#This Row],[Pcs per Box]] -> 52 | K23: =SUMIF('Sales Log Table'!C:C, Table1[[#This Row],[Medicine ID]], 'Sales Log Table'!E:E) -> 0 | L23: =Table1[[#This Row],[Total Received]] - Table1[[#This Row],[Total Sold]] -> 52 | M23: 20 | N23: 46563 | O23: =IF(Table1[[#This Row],[Current Stock]] <= Table1[[#This Row],[Min Stock]], "REORDER NOW", "Good") -> Good | P23: =(Table1[[#This Row],[Unit Price]] - Table1[[#This Row],[Cost Per Pc]]) * Table1[[#This Row],[Total Sold]] -> 0 | R23: =(Table1[[#This Row],[Total Received]] / Table1[[#This Row],[Pcs per Box]]) * Table1[[#This Row],[Cost Price]] -> 374.4 | S23: =SUM($R$3:Table1[[#This Row],[Annual Consumption Value]]) / SUM(Table1[Annual Consumption Value]) -> 0.15136484 | T23: =IF(Table1[[#This Row],[Cumulative %]]<=0.8, "A", IF(Table1[[#This Row],[Cumulative %]]<=0.95, "B", "C")) -> A
A24: AN-002 | B24: Flubac 500 | C24: Flucloxacillin Sodium | D24: Capsule | E24: Antibiotic | F24: =(Table1[[#This Row],[Unit Price]] * 0.9) * Table1[[#This Row],[Pcs per Box]] -> 403.2 | G24: 32 | H24: =Table1[[#This Row],[Cost Price]]/Table1[[#This Row],[Pcs per Box]] -> 12.6 | I24: 14 | J24: =SUMIF('Stock In'!C:C, Table1[[#This Row],[Medicine ID]], 'Stock In'!E:E) * Table1[[#This Row],[Pcs per Box]] -> 128 | K24: =SUMIF('Sales Log Table'!C:C, Table1[[#This Row],[Medicine ID]], 'Sales Log Table'!E:E) -> 0 | L24: =Table1[[#This Row],[Total Received]] - Table1[[#This Row],[Total Sold]] -> 128 | M24: 80 | N24: 46563 | O24: =IF(Table1[[#This Row],[Current Stock]] <= Table1[[#This Row],[Min Stock]], "REORDER NOW", "Good") -> Good | P24: =(Table1[[#This Row],[Unit Price]] - Table1[[#This Row],[Cost Per Pc]]) * Table1[[#This Row],[Total Sold]] -> 0 | R24: =(Table1[[#This Row],[Total Received]] / Table1[[#This Row],[Pcs per Box]]) * Table1[[#This Row],[Cost Price]] -> 1612.8 | S24: =SUM($R$3:Table1[[#This Row],[Annual Consumption Value]]) / SUM(Table1[Annual Consumption Value]) -> 0.15728709 | T24: =IF(Table1[[#This Row],[Cumulative %]]<=0.8, "A", IF(Table1[[#This Row],[Cumulative %]]<=0.95, "B", "C")) -> A
A25: AN-003 | B25: Flucloxin 250 | C25: Flucloxacillin Sodium | D25: Capsule | E25: Antibiotic | F25: =(Table1[[#This Row],[Unit Price]] * 0.9) * Table1[[#This Row],[Pcs per Box]] -> 519.3 | G25: 100 | H25: =Table1[[#This Row],[Cost Price]]/Table1[[#This Row],[Pcs per Box]] -> 5.193 | I25: 5.77 | J25: =SUMIF('Stock In'!C:C, Table1[[#This Row],[Medicine ID]], 'Stock In'!E:E) * Table1[[#This Row],[Pcs per Box]] -> 500 | K25: =SUMIF('Sales Log Table'!C:C, Table1[[#This Row],[Medicine ID]], 'Sales Log Table'!E:E) -> 0 | L25: =Table1[[#This Row],[Total Received]] - Table1[[#This Row],[Total Sold]] -> 500 | M25: 30 | N25: 46563 | O25: =IF(Table1[[#This Row],[Current Stock]] <= Table1[[#This Row],[Min Stock]], "REORDER NOW", "Good") -> Good | P25: =(Table1[[#This Row],[Unit Price]] - Table1[[#This Row],[Cost Per Pc]]) * Table1[[#This Row],[Total Sold]] -> 0 | R25: =(Table1[[#This Row],[Total Received]] / Table1[[#This Row],[Pcs per Box]]) * Table1[[#This Row],[Cost Price]] -> 2596.5 | S25: =SUM($R$3:Table1[[#This Row],[Annual Consumption Value]]) / SUM(Table1[Annual Consumption Value]) -> 0.16682152 | T25: =IF(Table1[[#This Row],[Cumulative %]]<=0.8, "A", IF(Table1[[#This Row],[Cumulative %]]<=0.95, "B", "C")) -> A
A26: AN-004 | B26: Flucloxin 500 | C26: Flucloxacillin Sodium | D26: Capsule | E26: Antibiotic | F26: =(Table1[[#This Row],[Unit Price]] * 0.9) * Table1[[#This Row],[Pcs per Box]] -> 378 | G26: 40 | H26: =Table1[[#This Row],[Cost Price]]/Table1[[#This Row],[Pcs per Box]] -> 9.45 | I26: 10.5 | J26: =SUMIF('Stock In'!C:C, Table1[[#This Row],[Medicine ID]], 'Stock In'!E:E) * Table1[[#This Row],[Pcs per Box]] -> 200 | K26: =SUMIF('Sales Log Table'!C:C, Table1[[#This Row],[Medicine ID]], 'Sales Log Table'!E:E) -> 0 | L26: =Table1[[#This Row],[Total Received]] - Table1[[#This Row],[Total Sold]] -> 200 | M26: 80 | N26: 46563 | O26: =IF(Table1[[#This Row],[Current Stock]] <= Table1[[#This Row],[Min Stock]], "REORDER NOW", "Good") -> Good | P26: =(Table1[[#This Row],[Unit Price]] - Table1[[#This Row],[Cost Per Pc]]) * Table1[[#This Row],[Total Sold]] -> 0 | R26: =(Table1[[#This Row],[Total Received]] / Table1[[#This Row],[Pcs per Box]]) * Table1[[#This Row],[Cost Price]] -> 1890 | S26: =SUM($R$3:Table1[[#This Row],[Annual Consumption Value]]) / SUM(Table1[Annual Consumption Value]) -> 0.17376166 | T26: =IF(Table1[[#This Row],[Cumulative %]]<=0.8, "A", IF(Table1[[#This Row],[Cumulative %]]<=0.95, "B", "C")) -> A
A27: AN-005 | B27: Zimax 500 | C27: Azithromycin | D27: Tablet | E27: Antibiotic | F27: =(Table1[[#This Row],[Unit Price]] * 0.9) * Table1[[#This Row],[Pcs per Box]] -> 648 | G27: 18 | H27: =Table1[[#This Row],[Cost Price]]/Table1[[#This Row],[Pcs per Box]] -> 36 | I27: 40 | J27: =SUMIF('Stock In'!C:C, Table1[[#This Row],[Medicine ID]], 'Stock In'!E:E) * Table1[[#This Row],[Pcs per Box]] -> 144 | K27: =SUMIF('Sales Log Table'!C:C, Table1[[#This Row],[Medicine ID]], 'Sales Log Table'!E:E) -> 3 | L27: =Table1[[#This Row],[Total Received]] - Table1[[#This Row],[Total Sold]] -> 141 | M27: 40 | N27: 46563 | O27: =IF(Table1[[#This Row],[Current Stock]] <= Table1[[#This Row],[Min Stock]], "REORDER NOW", "Good") -> Good | P27: =(Table1[[#This Row],[Unit Price]] - Table1[[#This Row],[Cost Per Pc]]) * Table1[[#This Row],[Total Sold]] -> 12 | R27: =(Table1[[#This Row],[Total Received]] / Table1[[#This Row],[Pcs per Box]]) * Table1[[#This Row],[Cost Price]] -> 5184 | S27: =SUM($R$3:Table1[[#This Row],[Annual Consumption Value]]) / SUM(Table1[Annual Consumption Value]) -> 0.19279747 | T27: =IF(Table1[[#This Row],[Cumulative %]]<=0.8, "A", IF(Table1[[#This Row],[Cumulative %]]<=0.95, "B", "C")) -> A
A28: AN-006 | B28: AZ 500 | C28: Azithromycin | D28: Tablet | E28: Antibiotic | F28: =(Table1[[#This Row],[Unit Price]] * 0.9) * Table1[[#This Row],[Pcs per Box]] -> 594 | G28: 12 | H28: =Table1[[#This Row],[Cost Price]]/Table1[[#This Row],[Pcs per Box]] -> 49.5 | I28: 55 | J28: =SUMIF('Stock In'!C:C, Table1[[#This Row],[Medicine ID]], 'Stock In'!E:E) * Table1[[#This Row],[Pcs per Box]] -> 72 | K28: =SUMIF('Sales Log Table'!C:C, Table1[[#This Row],[Medicine ID]], 'Sales Log Table'!E:E) -> 0 | L28: =Table1[[#This Row],[Total Received]] - Table1[[#This Row],[Total Sold]] -> 72 | M28: 50 | N28: 46563 | O28: =IF(Table1[[#This Row],[Current Stock]] <= Table1[[#This Row],[Min Stock]], "REORDER NOW", "Good") -> Good | P28: =(Table1[[#This Row],[Unit Price]] - Table1[[#This Row],[Cost Per Pc]]) * Table1[[#This Row],[Total Sold]] -> 0 | R28: =(Table1[[#This Row],[Total Received]] / Table1[[#This Row],[Pcs per Box]]) * Table1[[#This Row],[Cost Price]] -> 3564 | S28: =SUM($R$3:Table1[[#This Row],[Annual Consumption Value]]) / SUM(Table1[Annual Consumption Value]) -> 0.20588459 | T28: =IF(Table1[[#This Row],[Cumulative %]]<=0.8, "A", IF(Table1[[#This Row],[Cumulative %]]<=0.95, "B", "C")) -> A
A29: AN-007 | B29: Zithrox 500 | C29: Azithromycin | D29: Tablet | E29: Antibiotic | F29: 422.43 | G29: 12 | H29: =Table1[[#This Row],[Cost Price]]/Table1[[#This Row],[Pcs per Box]] -> 35.2025 | I29: 40 | J29: =SUMIF('Stock In'!C:C, Table1[[#This Row],[Medicine ID]], 'Stock In'!E:E) * Table1[[#This Row],[Pcs per Box]] -> 96 | K29: =SUMIF('Sales Log Table'!C:C, Table1[[#This Row],[Medicine ID]], 'Sales Log Table'!E:E) -> 0 | L29: =Table1[[#This Row],[Total Received]] - Table1[[#This Row],[Total Sold]] -> 96 | M29: 30 | N29: 46563 | O29: =IF(Table1[[#This Row],[Current Stock]] <= Table1[[#This Row],[Min Stock]], "REORDER NOW", "Good") -> Good | P29: =(Table1[[#This Row],[Unit Price]] - Table1[[#This Row],[Cost Per Pc]]) * Table1[[#This Row],[Total Sold]] -> 0 | R29: =(Table1[[#This Row],[Total Received]] / Table1[[#This Row],[Pcs per Box]]) * Table1[[#This Row],[Cost Price]] -> 3379.44 | S29: =SUM($R$3:Table1[[#This Row],[Annual Consumption Value]]) / SUM(Table1[Annual Consumption Value]) -> 0.218294 | T29: =IF(Table1[[#This Row],[Cumulative %]]<=0.8, "A", IF(Table1[[#This Row],[Cumulative %]]<=0.95, "B", "C")) -> A
A30: AN-008 | B30: Azomac 500 | C30: Azithromycin | D30: Tablet | E30: Antibiotic | F30: =(Table1[[#This Row],[Unit Price]] * 0.9) * Table1[[#This Row],[Pcs per Box]] -> 486 | G30: 12 | H30: =Table1[[#This Row],[Cost Price]]/Table1[[#This Row],[Pcs per Box]] -> 40.5 | I30: 45 | J30: =SUMIF('Stock In'!C:C, Table1[[#This Row],[Medicine ID]], 'Stock In'!E:E) * Table1[[#This Row],[Pcs per Box]] -> 120 | K30: =SUMIF('Sales Log Table'!C:C, Table1[[#This Row],[Medicine ID]], 'Sales Log Table'!E:E) -> 0 | L30: =Table1[[#This Row],[Total Received]] - Table1[[#This Row],[Total Sold]] -> 120 | M30: 45 | N30: 46563 | O30: =IF(Table1[[#This Row],[Current Stock]] <= Table1[[#This Row],[Min Stock]], "REORDER NOW", "Good") -> Good | P30: =(Table1[[#This Row],[Unit Price]] - Table1[[#This Row],[Cost Per Pc]]) * Table1[[#This Row],[Total Sold]] -> 0 | R30: =(Table1[[#This Row],[Total Received]] / Table1[[#This Row],[Pcs per Box]]) * Table1[[#This Row],[Cost Price]] -> 4860 | S30: =SUM($R$3:Table1[[#This Row],[Annual Consumption Value]]) / SUM(Table1[Annual Consumption Value]) -> 0.23614007 | T30: =IF(Table1[[#This Row],[Cumulative %]]<=0.8, "A", IF(Table1[[#This Row],[Cumulative %]]<=0.95, "B", "C")) -> A
A31: AN-009 | B31: Roxim 200 | C31: Cefixime | D31: Capsule | E31: Antibiotic | F31: =(Table1[[#This Row],[Unit Price]] * 0.9) * Table1[[#This Row],[Pcs per Box]] -> 576 | G31: 16 | H31: =Table1[[#This Row],[Cost Price]]/Table1[[#This Row],[Pcs per Box]] -> 36 | I31: 40 | J31: =SUMIF('Stock In'!C:C, Table1[[#This Row],[Medicine ID]], 'Stock In'!E:E) * Table1[[#This Row],[Pcs per Box]] -> 48 | K31: =SUMIF('Sales Log Table'!C:C, Table1[[#This Row],[Medicine ID]], 'Sales Log Table'!E:E) -> 0 | L31: =Table1[[#This Row],[Total Received]] - Table1[[#This Row],[Total Sold]] -> 48 | M31: 16 | N31: 46563 | O31: =IF(Table1[[#This Row],[Current Stock]] <= Table1[[#This Row],[Min Stock]], "REORDER NOW", "Good") -> Good | P31: =(Table1[[#This Row],[Unit Price]] - Table1[[#This Row],[Cost Per Pc]]) * Table1[[#This Row],[Total Sold]] -> 0 | R31: =(Table1[[#This Row],[Total Received]] / Table1[[#This Row],[Pcs per Box]]) * Table1[[#This Row],[Cost Price]] -> 1728 | S31: =SUM($R$3:Table1[[#This Row],[Annual Consumption Value]]) / SUM(Table1[Annual Consumption Value]) -> 0.24248534 | T31: =IF(Table1[[#This Row],[Cumulative %]]<=0.8, "A", IF(Table1[[#This Row],[Cumulative %]]<=0.95, "B", "C")) -> A
A32: AN-010 | B32: Roxim 400 | C32: Cefixime | D32: Capsule | E32: Antibiotic | F32: =(Table1[[#This Row],[Unit Price]] * 0.9) * Table1[[#This Row],[Pcs per Box]] -> 495 | G32: 10 | H32: =Table1[[#This Row],[Cost Price]]/Table1[[#This Row],[Pcs per Box]] -> 49.5 | I32: 55 | J32: =SUMIF('Stock In'!C:C, Table1[[#This Row],[Medicine ID]], 'Stock In'!E:E) * Table1[[#This Row],[Pcs per Box]] -> 170 | K32: =SUMIF('Sales Log Table'!C:C, Table1[[#This Row],[Medicine ID]], 'Sales Log Table'!E:E) -> 0 | L32: =Table1[[#This Row],[Total Received]] - Table1[[#This Row],[Total Sold]] -> 170 | M32: 20 | N32: 46563 | O32: =IF(Table1[[#This Row],[Current Stock]] <= Table1[[#This Row],[Min Stock]], "REORDER NOW", "Good") -> Good | P32: =(Table1[[#This Row],[Unit Price]] - Table1[[#This Row],[Cost Per Pc]]) * Table1[[#This Row],[Total Sold]] -> 0 | R32: =(Table1[[#This Row],[Total Received]] / Table1[[#This Row],[Pcs per Box]]) * Table1[[#This Row],[Cost Price]] -> 8415 | S32: =SUM($R$3:Table1[[#This Row],[Annual Consumption Value]]) / SUM(Table1[Annual Consumption Value]) -> 0.27338549 | T32: =IF(Table1[[#This Row],[Cumulative %]]<=0.8, "A", IF(Table1[[#This Row],[Cumulative %]]<=0.95, "B", "C")) -> A
A33: AN-011 | B33: Cef-3 | C33: Cefixime | D33: Capsule | E33: Antibiotic | F33: =(Table1[[#This Row],[Unit Price]] * 0.9) * Table1[[#This Row],[Pcs per Box]] -> 567 | G33: 14 | H33: =Table1[[#This Row],[Cost Price]]/Table1[[#This Row],[Pcs per Box]] -> 40.5 | I33: 45 | J33: =SUMIF('Stock In'!C:C, Table1[[#This Row],[Medicine ID]], 'Stock In'!E:E) * Table1[[#This Row],[Pcs per Box]] -> 42 | K33: =SUMIF('Sales Log Table'!C:C, Table1[[#This Row],[Medicine ID]], 'Sales Log Table'!E:E) -> 0 | L33: =Table1[[#This Row],[Total Received]] - Table1[[#This Row],[Total Sold]] -> 42 | M33: 30 | N33: 46563 | O33: =IF(Table1[[#This Row],[Current Stock]] <= Table1[[#This Row],[Min Stock]], "REORDER NOW", "Good") -> Good | P33: =(Table1[[#This Row],[Unit Price]] - Table1[[#This Row],[Cost Per Pc]]) * Table1[[#This Row],[Total Sold]] -> 0 | R33: =(Table1[[#This Row],[Total Received]] / Table1[[#This Row],[Pcs per Box]]) * Table1[[#This Row],[Cost Price]] -> 1701 | S33: =SUM($R$3:Table1[[#This Row],[Annual Consumption Value]]) / SUM(Table1[Annual Consumption Value]) -> 0.27963161 | T33: =IF(Table1[[#This Row],[Cumulative %]]<=0.8, "A", IF(Table1[[#This Row],[Cumulative %]]<=0.95, "B", "C")) -> A
A34: AN-012 | B34: Cef-3 DS | C34: Cefixime | D34: Capsule | E34: Antibiotic | F34: =(Table1[[#This Row],[Unit Price]] * 0.9) * Table1[[#This Row],[Pcs per Box]] -> 756 | G34: 14 | H34: =Table1[[#This Row],[Cost Price]]/Table1[[#This Row],[Pcs per Box]] -> 54 | I34: 60 | J34: =SUMIF('Stock In'!C:C, Table1[[#This Row],[Medicine ID]], 'Stock In'!E:E) * Table1[[#This Row],[Pcs per Box]] -> 70 | K34: =SUMIF('Sales Log Table'!C:C, Table1[[#This Row],[Medicine ID]], 'Sales Log Table'!E:E) -> 0 | L34: =Table1[[#This Row],[Total Received]] - Table1[[#This Row],[Total Sold]] -> 70 | M34: 46 | N34: 46563 | O34: =IF(Table1[[#This Row],[Current Stock]] <= Table1[[#This Row],[Min Stock]], "REORDER NOW", "Good") -> Good | P34: =(Table1[[#This Row],[Unit Price]] - Table1[[#This Row],[Cost Per Pc]]) * Table1[[#This Row],[Total Sold]] -> 0 | R34: =(Table1[[#This Row],[Total Received]] / Table1[[#This Row],[Pcs per Box]]) * Table1[[#This Row],[Cost Price]] -> 3780 | S34: =SUM($R$3:Table1[[#This Row],[Annual Consumption Value]]) / SUM(Table1[Annual Consumption Value]) -> 0.29351189 | T34: =IF(Table1[[#This Row],[Cumulative %]]<=0.8, "A", IF(Table1[[#This Row],[Cumulative %]]<=0.95, "B", "C")) -> A
A35: AN-013 | B35: Crfim-3 | C35: Cefixime | D35: Capsule | E35: Antibiotic | F35: =(Table1[[#This Row],[Unit Price]] * 0.9) * Table1[[#This Row],[Pcs per Box]] -> 428.4 | G35: 14 | H35: =Table1[[#This Row],[Cost Price]]/Table1[[#This Row],[Pcs per Box]] -> 30.6 | I35: 34 | J35: =SUMIF('Stock In'!C:C, Table1[[#This Row],[Medicine ID]], 'Stock In'!E:E) * Table1[[#This Row],[Pcs per Box]] -> 84 | K35: =SUMIF('Sales Log Table'!C:C, Table1[[#This Row],[Medicine ID]], 'Sales Log Table'!E:E) -> 0 | L35: =Table1[[#This Row],[Total Received]] - Table1[[#This Row],[Total Sold]] -> 84 | M35: 76 | N35: 46563 | O35: =IF(Table1[[#This Row],[Current Stock]] <= Table1[[#This Row],[Min Stock]], "REORDER NOW", "Good") -> Good | P35: =(Table1[[#This Row],[Unit Price]] - Table1[[#This Row],[Cost Per Pc]]) * Table1[[#This Row],[Total Sold]] -> 0 | R35: =(Table1[[#This Row],[Total Received]] / Table1[[#This Row],[Pcs per Box]]) * Table1[[#This Row],[Cost Price]] -> 2570.4 | S35: =SUM($R$3:Table1[[#This Row],[Annual Consumption Value]]) / SUM(Table1[Annual Consumption Value]) -> 0.30295048 | T35: =IF(Table1[[#This Row],[Cumulative %]]<=0.8, "A", IF(Table1[[#This Row],[Cumulative %]]<=0.95, "B", "C")) -> A
A36: AN-014 | B36: Cefim-3 DS | C36: Cefixime | D36: Capsule | E36: Antibiotic | F36: =(Table1[[#This Row],[Unit Price]] * 0.9) * Table1[[#This Row],[Pcs per Box]] -> 756 | G36: 14 | H36: =Table1[[#This Row],[Cost Price]]/Table1[[#This Row],[Pcs per Box]] -> 54 | I36: 60 | J36: =SUMIF('Stock In'!C:C, Table1[[#This Row],[Medicine ID]], 'Stock In'!E:E) * Table1[[#This Row],[Pcs per Box]] -> 84 | K36: =SUMIF('Sales Log Table'!C:C, Table1[[#This Row],[Medicine ID]], 'Sales Log Table'!E:E) -> 0 | L36: =Table1[[#This Row],[Total Received]] - Table1[[#This Row],[Total Sold]] -> 84 | M36: 65 | N36: 46563 | O36: =IF(Table1[[#This Row],[Current Stock]] <= Table1[[#This Row],[Min Stock]], "REORDER NOW", "Good") -> Good | P36: =(Table1[[#This Row],[Unit Price]] - Table1[[#This Row],[Cost Per Pc]]) * Table1[[#This Row],[Total Sold]] -> 0 | R36: =(Table1[[#This Row],[Total Received]] / Table1[[#This Row],[Pcs per Box]]) * Table1[[#This Row],[Cost Price]] -> 4536 | S36: =SUM($R$3:Table1[[#This Row],[Annual Consumption Value]]) / SUM(Table1[Annual Consumption Value]) -> 0.31960682 | T36: =IF(Table1[[#This Row],[Cumulative %]]<=0.8, "A", IF(Table1[[#This Row],[Cumulative %]]<=0.95, "B", "C")) -> A
A37: AN-015 | B37: Denvar 200 | C37: Cefixime | D37: Capsule | E37: Antibiotic | F37: =(Table1[[#This Row],[Unit Price]] * 0.9) * Table1[[#This Row],[Pcs per Box]] -> 864 | G37: 24 | H37: =Table1[[#This Row],[Cost Price]]/Table1[[#This Row],[Pcs per Box]] -> 36 | I37: 40 | J37: =SUMIF('Stock In'!C:C, Table1[[#This Row],[Medicine ID]], 'Stock In'!E:E) * Table1[[#This Row],[Pcs per Box]] -> 72 | K37: =SUMIF('Sales Log Table'!C:C, Table1[[#This Row],[Medicine ID]], 'Sales Log Table'!E:E) -> 0 | L37: =Table1[[#This Row],[Total Received]] - Table1[[#This Row],[Total Sold]] -> 72 | M37: 47 | N37: 46563 | O37: =IF(Table1[[#This Row],[Current Stock]] <= Table1[[#This Row],[Min Stock]], "REORDER NOW", "Good") -> Good | P37: =(Table1[[#This Row],[Unit Price]] - Table1[[#This Row],[Cost Per Pc]]) * Table1[[#This Row],[Total Sold]] -> 0 | R37: =(Table1[[#This Row],[Total Received]] / Table1[[#This Row],[Pcs per Box]]) * Table1[[#This Row],[Cost Price]] -> 2592 | S37: =SUM($R$3:Table1[[#This Row],[Annual Consumption Value]]) / SUM(Table1[Annual Consumption Value]) -> 0.32912472 | T37: =IF(Table1[[#This Row],[Cumulative %]]<=0.8, "A", IF(Table1[[#This Row],[Cumulative %]]<=0.95, "B", "C")) -> A
A38: AN-016 | B38: Denvar 400 | C38: Cefixime | D38: Capsule | E38: Antibiotic | F38: =(Table1[[#This Row],[Unit Price]] * 0.9) * Table1[[#This Row],[Pcs per Box]] -> 972 | G38: 18 | H38: =Table1[[#This Row],[Cost Price]]/Table1[[#This Row],[Pcs per Box]] -> 54 | I38: 60 | J38: =SUMIF('Stock In'!C:C, Table1[[#This Row],[Medicine ID]], 'Stock In'!E:E) * Table1[[#This Row],[Pcs per Box]] -> 216 | K38: =SUMIF('Sales Log Table'!C:C, Table1[[#This Row],[Medicine ID]], 'Sales Log Table'!E:E) -> 0 | L38: =Table1[[#This Row],[Total Received]] - Table1[[#This Row],[Total Sold]] -> 216 | M38: 78 | N38: 46563 | O38: =IF(Table1[[#This Row],[Current Stock]] <= Table1[[#This Row],[Min Stock]], "REORDER NOW", "Good") -> Good | P38: =(Table1[[#This Row],[Unit Price]] - Table1[[#This Row],[Cost Per Pc]]) * Table1[[#This Row],[Total Sold]] -> 0 | R38: =(Table1[[#This Row],[Total Received]] / Table1[[#This Row],[Pcs per Box]]) * Table1[[#This Row],[Cost Price]] -> 11664 | S38: =SUM($R$3:Table1[[#This Row],[Annual Consumption Value]]) / SUM(Table1[Annual Consumption Value]) -> 0.37195529 | T38: =IF(Table1[[#This Row],[Cumulative %]]<=0.8, "A", IF(Table1[[#This Row],[Cumulative %]]<=0.95, "B", "C")) -> A
A39: AN-017 | B39: Fix-A | C39: Cefixime | D39: Capsule | E39: Antibiotic | F39: =(Table1[[#This Row],[Unit Price]] * 0.9) * Table1[[#This Row],[Pcs per Box]] -> 567 | G39: 14 | H39: =Table1[[#This Row],[Cost Price]]/Table1[[#This Row],[Pcs per Box]] -> 40.5 | I39: 45 | J39: =SUMIF('Stock In'!C:C, Table1[[#This Row],[Medicine ID]], 'Stock In'!E:E) * Table1[[#This Row],[Pcs per Box]] -> 42 | K39: =SUMIF('Sales Log Table'!C:C, Table1[[#This Row],[Medicine ID]], 'Sales Log Table'!E:E) -> 0 | L39: =Table1[[#This Row],[Total Received]] - Table1[[#This Row],[Total Sold]] -> 42 | M39: 29 | N39: 46563 | O39: =IF(Table1[[#This Row],[Current Stock]] <= Table1[[#This Row],[Min Stock]], "REORDER NOW", "Good") -> Good | P39: =(Table1[[#This Row],[Unit Price]] - Table1[[#This Row],[Cost Per Pc]]) * Table1[[#This Row],[Total Sold]] -> 0 | R39: =(Table1[[#This Row],[Total Received]] / Table1[[#This Row],[Pcs per Box]]) * Table1[[#This Row],[Cost Price]] -> 1701 | S39: =SUM($R$3:Table1[[#This Row],[Annual Consumption Value]]) / SUM(Table1[Annual Consumption Value]) -> 0.37820142 | T39: =IF(Table1[[#This Row],[Cumulative %]]<=0.8, "A", IF(Table1[[#This Row],[Cumulative %]]<=0.95, "B", "C")) -> A
A40: AN-018 | B40: Fix-A DS | C40: Cefixime | D40: Capsule | E40: Antibiotic | F40: =(Table1[[#This Row],[Unit Price]] * 0.9) * Table1[[#This Row],[Pcs per Box]] -> 756 | G40: 14 | H40: =Table1[[#This Row],[Cost Price]]/Table1[[#This Row],[Pcs per Box]] -> 54 | I40: 60 | J40: =SUMIF('Stock In'!C:C, Table1[[#This Row],[Medicine ID]], 'Stock In'!E:E) * Table1[[#This Row],[Pcs per Box]] -> 14 | K40: =SUMIF('Sales Log Table'!C:C, Table1[[#This Row],[Medicine ID]], 'Sales Log Table'!E:E) -> 0 | L40: =Table1[[#This Row],[Total Received]] - Table1[[#This Row],[Total Sold]] -> 14 | M40: 7 | N40: 46563 | O40: =IF(Table1[[#This Row],[Current Stock]] <= Table1[[#This Row],[Min Stock]], "REORDER NOW", "Good") -> Good | P40: =(Table1[[#This Row],[Unit Price]] - Table1[[#This Row],[Cost Per Pc]]) * Table1[[#This Row],[Total Sold]] -> 0 | R40: =(Table1[[#This Row],[Total Received]] / Table1[[#This Row],[Pcs per Box]]) * Table1[[#This Row],[Cost Price]] -> 756 | S40: =SUM($R$3:Table1[[#This Row],[Annual Consumption Value]]) / SUM(Table1[Annual Consumption Value]) -> 0.38097747 | T40: =IF(Table1[[#This Row],[Cumulative %]]<=0.8, "A", IF(Table1[[#This Row],[Cumulative %]]<=0.95, "B", "C")) -> A
...

Sheet Sales Log Table
A1: DAILY SALES LOG
A2: invoice ID | B2: Date | C2: Medicine ID | D2: Medicine Name | E2: Qty Sold | F2: Total Price | G2: Payment Method
A3: INV-260517-01 | B3: 17-05-2026 | C3: =_xlfn.XLOOKUP(Table4[[#This Row],[Medicine Name]], 'Medicine Master Table'!B:B, 'Medicine Master Table'!A:A, "Not Found") -> PA-001 | D3: Napa | E3: 30 | F3: =_xlfn.XLOOKUP(Table4[[#This Row],[Medicine ID]], 'Medicine Master Table'!A:A, 'Medicine Master Table'!I:I, 0) * Table4[[#This Row],[Qty Sold]] -> 36 | G3: Cash
A4: INV-260517-01 | B4: 17-05-2026 | C4: =_xlfn.XLOOKUP(Table4[[#This Row],[Medicine Name]], 'Medicine Master Table'!B:B, 'Medicine Master Table'!A:A, "Not Found") -> PA-002 | D4: Napa Extra | E4: 10 | F4: =_xlfn.XLOOKUP(Table4[[#This Row],[Medicine ID]], 'Medicine Master Table'!A:A, 'Medicine Master Table'!I:I, 0) * Table4[[#This Row],[Qty Sold]] -> 25 | G4: Cash
A5: INV-260524-01 | B5: 24-05-2026 | C5: =_xlfn.XLOOKUP(Table4[[#This Row],[Medicine Name]], 'Medicine Master Table'!B:B, 'Medicine Master Table'!A:A, "Not Found") -> NE-004 | D5: Benzit | E5: 10 | F5: =_xlfn.XLOOKUP(Table4[[#This Row],[Medicine ID]], 'Medicine Master Table'!A:A, 'Medicine Master Table'!I:I, 0) * Table4[[#This Row],[Qty Sold]] -> 50 | G5: Cash
A6: INV-260524-01 | B6: 24-05-2026 | C6: =_xlfn.XLOOKUP(Table4[[#This Row],[Medicine Name]], 'Medicine Master Table'!B:B, 'Medicine Master Table'!A:A, "Not Found") -> GA-004 | D6: Exium | E6: 10 | F6: =_xlfn.XLOOKUP(Table4[[#This Row],[Medicine ID]], 'Medicine Master Table'!A:A, 'Medicine Master Table'!I:I, 0) * Table4[[#This Row],[Qty Sold]] -> 90 | G6: Cash
A7: INV-260524-01 | B7: 24-05-2026 | C7: =_xlfn.XLOOKUP(Table4[[#This Row],[Medicine Name]], 'Medicine Master Table'!B:B, 'Medicine Master Table'!A:A, "Not Found") -> GA-003 | D7: Seclo | E7: 10 | F7: =_xlfn.XLOOKUP(Table4[[#This Row],[Medicine ID]], 'Medicine Master Table'!A:A, 'Medicine Master Table'!I:I, 0) * Table4[[#This Row],[Qty Sold]] -> 60 | G7: Cash
A8: INV-260524-01 | B8: 24-05-2026 | C8: =_xlfn.XLOOKUP(Table4[[#This Row],[Medicine Name]], 'Medicine Master Table'!B:B, 'Medicine Master Table'!A:A, "Not Found") -> AL-016 | D8: Bilbest 20mg | E8: 10 | F8: =_xlfn.XLOOKUP(Table4[[#This Row],[Medicine ID]], 'Medicine Master Table'!A:A, 'Medicine Master Table'!I:I, 0) * Table4[[#This Row],[Qty Sold]] -> 150 | G8: Cash
A9: INV-260524-01 | B9: 24-05-2026 | C9: =_xlfn.XLOOKUP(Table4[[#This Row],[Medicine Name]], 'Medicine Master Table'!B:B, 'Medicine Master Table'!A:A, "Not Found") -> NE-001 | D9: Anzet | E9: 10 | F9: =_xlfn.XLOOKUP(Table4[[#This Row],[Medicine ID]], 'Medicine Master Table'!A:A, 'Medicine Master Table'!I:I, 0) * Table4[[#This Row],[Qty Sold]] -> 50 | G9: Cash
A10: INV-260524-01 | B10: 24-05-2026 | C10: =_xlfn.XLOOKUP(Table4[[#This Row],[Medicine Name]], 'Medicine Master Table'!B:B, 'Medicine Master Table'!A:A, "Not Found") -> GA-005 | D10: Maxpro 20mg | E10: 14 | F10: =_xlfn.XLOOKUP(Table4[[#This Row],[Medicine ID]], 'Medicine Master Table'!A:A, 'Medicine Master Table'!I:I, 0) * Table4[[#This Row],[Qty Sold]] -> 98 | G10: Cash
A11: INV-260524-01 | B11: 24-05-2026 | C11: =_xlfn.XLOOKUP(Table4[[#This Row],[Medicine Name]], 'Medicine Master Table'!B:B, 'Medicine Master Table'!A:A, "Not Found") -> AL-005 | D11: Alatrol | E11: 10 | F11: =_xlfn.XLOOKUP(Table4[[#This Row],[Medicine ID]], 'Medicine Master Table'!A:A, 'Medicine Master Table'!I:I, 0) * Table4[[#This Row],[Qty Sold]] -> 30 | G11: Cash
A12: INV-260524-01 | B12: 24-05-2026 | C12: =_xlfn.XLOOKUP(Table4[[#This Row],[Medicine Name]], 'Medicine Master Table'!B:B, 'Medicine Master Table'!A:A, "Not Found") -> AN-005 | D12: Zimax 500 | E12: 3 | F12: =_xlfn.XLOOKUP(Table4[[#This Row],[Medicine ID]], 'Medicine Master Table'!A:A, 'Medicine Master Table'!I:I, 0) * Table4[[#This Row],[Qty Sold]] -> 120 | G12: Cash
A13: INV-260524-02 | B13: 24-05-2026 | C13: =_xlfn.XLOOKUP(Table4[[#This Row],[Medicine Name]], 'Medicine Master Table'!B:B, 'Medicine Master Table'!A:A, "Not Found") -> AL-015 | D13: Ebatin | E13: 10 | F13: =_xlfn.XLOOKUP(Table4[[#This Row],[Medicine ID]], 'Medicine Master Table'!A:A, 'Medicine Master Table'!I:I, 0) * Table4[[#This Row],[Qty Sold]] -> 100 | G13: Cash
A14: INV-260524-02 | B14: 24-05-2026 | C14: =_xlfn.XLOOKUP(Table4[[#This Row],[Medicine Name]], 'Medicine Master Table'!B:B, 'Medicine Master Table'!A:A, "Not Found") -> GA-003 | D14: Seclo | E14: 10 | F14: =_xlfn.XLOOKUP(Table4[[#This Row],[Medicine ID]], 'Medicine Master Table'!A:A, 'Medicine Master Table'!I:I, 0) * Table4[[#This Row],[Qty Sold]] -> 60 | G14: Cash
A15: INV-260524-03 | B15: 24-05-2026 | C15: =_xlfn.XLOOKUP(Table4[[#This Row],[Medicine Name]], 'Medicine Master Table'!B:B, 'Medicine Master Table'!A:A, "Not Found") -> CAL-007 | D15: Coralcin-D | E15: 50 | F15: =_xlfn.XLOOKUP(Table4[[#This Row],[Medicine ID]], 'Medicine Master Table'!A:A, 'Medicine Master Table'!I:I, 0) * Table4[[#This Row],[Qty Sold]] -> 550 | G15: Cash

Sheet Stock In
A1: INCOMING STOCK LOG
A2: Batch ID | B2: Date | C2: Medicine ID | D2: Medicine Name | E2: Qty Received | F2: Cost Price | G2: Supplier Name
A3: BCH-001 | B3: 16-05-2026 | C3: =_xlfn.XLOOKUP(Table5[[#This Row],[Medicine Name]], 'Medicine Master Table'!B:B, 'Medicine Master Table'!A:A, "Not Found") -> PA-001 | D3: Napa | E3: 4 | F3: =_xlfn.XLOOKUP(Table5[[#This Row],[Medicine ID]], 'Medicine Master Table'!A:A, 'Medicine Master Table'!F:F, 0) -> 550.8 | G3: Beximco Pharma
A4: BCH-002 | B4: 17-05-2026 | C4: =_xlfn.XLOOKUP(Table5[[#This Row],[Medicine Name]], 'Medicine Master Table'!B:B, 'Medicine Master Table'!A:A, "Not Found") -> PA-002 | D4: Napa Extra | E4: 2 | F4: =_xlfn.XLOOKUP(Table5[[#This Row],[Medicine ID]], 'Medicine Master Table'!A:A, 'Medicine Master Table'!F:F, 0) -> 297 | G4: Beximco Pharma
A5: BCH-003 | B5: 18-05-2026 | C5: =_xlfn.XLOOKUP(Table5[[#This Row],[Medicine Name]], 'Medicine Master Table'!B:B, 'Medicine Master Table'!A:A, "Not Found") -> PA-003 | D5: Napa Rapid | E5: 4 | F5: =_xlfn.XLOOKUP(Table5[[#This Row],[Medicine ID]], 'Medicine Master Table'!A:A, 'Medicine Master Table'!F:F, 0) -> 315.9 | G5: Beximco Pharma
A6: BCH-004 | B6: 19-05-2026 | C6: =_xlfn.XLOOKUP(Table5[[#This Row],[Medicine Name]], 'Medicine Master Table'!B:B, 'Medicine Master Table'!A:A, "Not Found") -> PA-004 | D6: Napa Extend | E6: 6 | F6: =_xlfn.XLOOKUP(Table5[[#This Row],[Medicine ID]], 'Medicine Master Table'!A:A, 'Medicine Master Table'!F:F, 0) -> 259.2 | G6: Beximco Pharma
A7: BCH-005 | B7: 19-05-2026 | C7: =_xlfn.XLOOKUP(Table5[[#This Row],[Medicine Name]], 'Medicine Master Table'!B:B, 'Medicine Master Table'!A:A, "Not Found") -> PA-005 | D7: Napa One | E7: 4 | F7: =_xlfn.XLOOKUP(Table5[[#This Row],[Medicine ID]], 'Medicine Master Table'!A:A, 'Medicine Master Table'!F:F, 0) -> 405 | G7: Beximco Pharma
A8: BCH-006 | B8: 19-05-2026 | C8: =_xlfn.XLOOKUP(Table5[[#This Row],[Medicine Name]], 'Medicine Master Table'!B:B, 'Medicine Master Table'!A:A, "Not Found") -> PA-006 | D8: Xpa | E8: 3 | F8: =_xlfn.XLOOKUP(Table5[[#This Row],[Medicine ID]], 'Medicine Master Table'!A:A, 'Medicine Master Table'!F:F, 0) -> 270 | G8: AristoPharma
A9: BCH-007 | B9: 19-05-2026 | C9: =_xlfn.XLOOKUP(Table5[[#This Row],[Medicine Name]], 'Medicine Master Table'!B:B, 'Medicine Master Table'!A:A, "Not Found") -> PA-007 | D9: Xpa XR | E9: 7 | F9: =_xlfn.XLOOKUP(Table5[[#This Row],[Medicine ID]], 'Medicine Master Table'!A:A, 'Medicine Master Table'!F:F, 0) -> 360 | G9: AristoPharma
A10: BCH-008 | B10: 19-05-2026 | C10: =_xlfn.XLOOKUP(Table5[[#This Row],[Medicine Name]], 'Medicine Master Table'!B:B, 'Medicine Master Table'!A:A, "Not Found") -> PA-008 | D10: Ace | E10: 8 | F10: =_xlfn.XLOOKUP(Table5[[#This Row],[Medicine ID]], 'Medicine Master Table'!A:A, 'Medicine Master Table'!F:F, 0) -> 540 | G10: Square Pharma
A11: BCH-009 | B11: 19-05-2026 | C11: =_xlfn.XLOOKUP(Table5[[#This Row],[Medicine Name]], 'Medicine Master Table'!B:B, 'Medicine Master Table'!A:A, "Not Found") -> PA-009 | D11: Ace Plus | E11: 3 | F11: =_xlfn.XLOOKUP(Table5[[#This Row],[Medicine ID]], 'Medicine Master Table'!A:A, 'Medicine Master Table'!F:F, 0) -> 451.8 | G11: Square Pharma
A12: BCH-010 | B12: 19-05-2026 | C12: =_xlfn.XLOOKUP(Table5[[#This Row],[Medicine Name]], 'Medicine Master Table'!B:B, 'Medicine Master Table'!A:A, "Not Found") -> PA-010 | D12: Ace Power | E12: 1 | F12: =_xlfn.XLOOKUP(Table5[[#This Row],[Medicine ID]], 'Medicine Master Table'!A:A, 'Medicine Master Table'!F:F, 0) -> 405 | G12: Square Pharma
A13: BCH-011 | B13: 19-05-2026 | C13: =_xlfn.XLOOKUP(Table5[[#This Row],[Medicine Name]], 'Medicine Master Table'!B:B, 'Medicine Master Table'!A:A, "Not Found") -> GA-001 | D13: Losectil 20 | E13: 6 | F13: =_xlfn.XLOOKUP(Table5[[#This Row],[Medicine ID]], 'Medicine Master Table'!A:A, 'Medicine Master Table'!F:F, 0) -> 1584.1 | G13: Eskayef Pharma
A14: BCH-012 | B14: 19-05-2026 | C14: =_xlfn.XLOOKUP(Table5[[#This Row],[Medicine Name]], 'Medicine Master Table'!B:B, 'Medicine Master Table'!A:A, "Not Found") -> GA-002 | D14: Losectil 40 | E14: 5 | F14: =_xlfn.XLOOKUP(Table5[[#This Row],[Medicine ID]], 'Medicine Master Table'!A:A, 'Medicine Master Table'!F:F, 0) -> 352.02 | G14: Square Pharma
... A124: BCH-123 | B124: 23-05-2026 | C124: =_xlfn.XLOOKUP(Table5[[#This Row],[Medicine Name]], 'Medicine Master Table'!B:B, 'Medicine Master Table'!A:A, "Not Found") -> AL-001 | D124: Fenadin 120mg | E124: 5 | F124: =_xlfn.XLOOKUP(Table5[[#This Row],[Medicine ID]], 'Medicine Master Table'!A:A, 'Medicine Master Table'!F:F, 0) -> 396.23 | G124: Renata Pharma
